Workbook
Name Slicer_Color: #N/A
Name Slicer_Country: #N/A
Name Slicer_Gender: #N/A
Name Slicer_iPhone_Model: #N/A
Name Slicer_Storage: #N/A
Name Slicer_Year: #N/A

Sheet iPhone_Sales_Data
A1: Order_ID | B1: Order_Date | C1: iPhone_Model | D1: Storage | E1: Color | F1: Country | G1: Gender | H1: Units_Sold | I1: Unit_Price | J1: Total_Sales | K1: Profit | L1: Month | M1: Year
A2: 10001 | B2: 45760 | C2: iPhone 15 Pro | D2: 256GB | E2: Blue | F2: USA | G2: Female | H2: 4 | I2: 1109 | J2: 4436 | K2: 908.01 | L2: Apr-2025 | M2: 2025
A3: 10002 | B3: 46093 | C3: iPhone 15 | D3: 128GB | E3: White | F3: India | G3: Female | H3: 3 | I3: 779 | J3: 2337 | K3: 432.52 | L3: Mar-2026 | M3: 2026
A4: 10003 | B4: 45928 | C4: iPhone 16 | D4: 128GB | E4: Blue | F4: India | G4: Female | H4: 1 | I4: 819 | J4: 819 | K4: 169.14 | L4: Sep-2025 | M4: 2025
A5: 10004 | B5: 45764 | C5: iPhone 16 Pro Max | D5: 128GB | E5: White | F5: India | G5: Male | H5: 1 | I5: 1199 | J5: 1199 | K5: 280.89 | L5: Apr-2025 | M5: 2025
A6: 10005 | B6: 45729 | C6: iPhone 16 Pro | D6: 256GB | E6: Purple | F6: India | G6: Female | H6: 3 | I6: 1219 | J6: 3657 | K6: 788.33 | L6: Mar-2025 | M6: 2025
A7: 10006 | B7: 45678 | C7: iPhone 16 Pro | D7: 128GB | E7: Blue | F7: Canada | G7: Female | H7: 3 | I7: 1079 | J7: 3237 | K7: 709.38 | L7: Jan-2025 | M7: 2025
A8: 10007 | B8: 45779 | C8: iPhone 16 | D8: 256GB | E8: Pink | F8: India | G8: Male | H8: 1 | I8: 919 | J8: 919 | K8: 160.77 | L8: May-2025 | M8: 2025
A9: 10008 | B9: 46124 | C9: iPhone 13 | D9: 512GB | E9: Purple | F9: India | G9: Male | H9: 4 | I9: 819 | J9: 3276 | K9: 508.41 | L9: Apr-2026 | M9: 2026
A10: 10009 | B10: 45872 | C10: iPhone 15 | D10: 256GB | E10: White | F10: India | G10: Female | H10: 4 | I10: 919 | J10: 3676 | K10: 647.67 | L10: Aug-2025 | M10: 2025
A11: 10010 | B11: 45988 | C11: iPhone 16 Pro Max | D11: 256GB | E11: Black | F11: Canada | G11: Male | H11: 1 | I11: 1299 | J11: 1299 | K11: 301.4 | L11: Nov-2025 | M11: 2025
A12: 10011 | B12: 46116 | C12: iPhone 15 Pro | D12: 256GB | E12: Purple | F12: India | G12: Male | H12: 3 | I12: 1109 | J12: 3327 | K12: 688.71 | L12: Apr-2026 | M12: 2026
A13: 10012 | B13: 45745 | C13: iPhone 14 | D13: 128GB | E13: Purple | F13: India | G13: Male | H13: 1 | I13: 699 | J13: 699 | K13: 116.01 | L13: Mar-2025 | M13: 2025
... A7001: 17000 | B7001: 45830 | C7001: iPhone 16 Pro | D7001: 512GB | E7001: Natural Titanium | F7001: Canada | G7001: Male | H7001: 1 | I7001: 1269 | J7001: 1269 | K7001: 280.23 | L7001: Jun-2025 | M7001: 2025

Sheet Dashboard

Sheet Questions
A1: 📱 iPhone Sales Dashboard
A3: 1️⃣ Top par KPI Cards
A5: Sabse upar 5 cards banao:
A7: KPI | B7: Kya dikhayega
A8: 💰 Total Sales | B8: Total revenue
A9: 📈 Total Profit | B9: Total profit
A10: 📦 Units Sold | B10: Kitne iPhones sold hue
A11: 🧾 Total Orders | B11: Total orders
A12: 💵 Average Order Value | B12: Average sales per order
A15: 2️⃣ Main Charts
A17: 📊 Sales by iPhone Model — Column Chart
A19: iPhone 13
A20: iPhone 14
A21: iPhone 15
A22: iPhone 15 Pro
A23: iPhone 15 Pro Max
A24: iPhone 16
A25: iPhone 16 Plus
A26: iPhone 16 Pro
A27: iPhone 16 Pro Max
A29: ➡️ Isse pata chalega kaunsa iPhone sabse zyada sell hua.
... A105: Isse dashboard interactive ho jayega.

Sheet pivot_table
A2: monthly unit | D2: I phone model | G2: country
A3: Row Labels | B3: Sum of Total_Sales | D3: Row Labels | E3: Sum of Units_Sold | G3: Row Labels | H3: Sum of Total_Sales
A4: Apr-2025 | B4: 712310 | D4: iPhone 13 | E4: 980 | G4: Australia | H4: 706681
A5: Apr-2026 | B5: 636894 | D5: iPhone 14 | E5: 1054 | G5: Canada | H5: 955755
A6: Aug-2025 | B6: 686976 | D6: iPhone 15 | E6: 1750 | G6: Germany | H6: 746459
A7: Aug-2026 | B7: 641254 | D7: iPhone 15 Pro | E7: 1599 | G7: India | H7: 5330229
A8: Dec-2025 | B8: 642422 | D8: iPhone 15 Pro Max | E8: 1340 | G8: Singapore | H8: 634976
A9: Feb-2025 | B9: 577337 | D9: iPhone 16 | E9: 2143 | G9: UAE | H9: 1329101
A10: Feb-2026 | B10: 583277 | D10: iPhone 16 Plus | E10: 1303 | G10: UK | H10: 1401610
A11: Jan-2025 | B11: 725814 | D11: iPhone 16 Pro | E11: 1942 | G11: USA | H11: 2344651
A12: Jan-2026 | B12: 702689 | D12: iPhone 16 Pro Max | E12: 1297 | G12: Grand Total | H12: 13449462
A13: Jul-2025 | B13: 689966 | D13: Grand Total | E13: 13408
A14: Jul-2026 | B14: 760765
A15: Jun-2025 | B15: 670193
A16: Jun-2026 | B16: 664466
A17: Mar-2025 | B17: 717268
A18: Mar-2026 | B18: 702302
A19: May-2025 | B19: 685982
A20: May-2026 | B20: 721420
A21: Nov-2025 | B21: 608632
A22: Oct-2025 | B22: 677031
A23: Sep-2025 | B23: 642464
A24: Grand Total | B24: 13449462
A27: storage | D27: gender | G27: color
A28: Row Labels | B28: Sum of Total_Sales | D28: Row Labels | E28: Sum of Total_Sales | G28: Row Labels | H28: Sum of Total_Sales
A29: 128GB | B29: 6317202 | D29: Female | E29: 6060720 | G29: Black | H29: 1912249
A30: 1TB | B30: 821077 | D30: Male | E30: 7388742 | G30: Blue | H30: 1868819
A31: 256GB | B31: 4091107 | D31: Grand Total | E31: 13449462 | G31: Green | H31: 2107778
A32: 512GB | B32: 2220076 | G32: Natural Titanium | H32: 1942136
A33: Grand Total | B33: 13449462 | G33: Pink | H33: 1976382
G34: Purple | H34: 1858706
G35: White | H35: 1783392
G36: Grand Total | H36: 13449462
A41: Sum of Total_Sales | C41: Sum of Profit | E41: Sum of Units_Sold
A42: 13449462 | C42: 2724614.9 | E42: 13408
A46: Count of Order_ID | C46: Average of Total_Sales
A47: 7000 | C47: 1921.3517
A53: Row Labels | B53: Sum of Total_Sales
A54: Apr-2025 | B54: 0.05296197
A55: Apr-2026 | B55: 0.047354608
...

Sheet Total_Sales_By_Month

Sheet  Unit_Sold_Models_Wise

Sheet Total_Sales_Country_Wise

Sheet Total_sales_storage_Wise

Sheet Unit_Sold_Gender_Wise

Sheet Chart_Data
A1: Model | B1: Units Sold | D1: Country | E1: Sales | G1: Storage | H1: Sales | J1: Color | K1: Units Sold | M1: Gender | N1: Sales | P1: Month | Q1: Sales
A2: iPhone 13 | B2: =SUMPRODUCT(--((#REF!="All")+(iPhone_Sales_Data!$M$2:$M$7001=#REF!)>0),--((#REF!="All")+(iPhone_Sales_Data!$G$2:$G$7001=#REF!)>0),--((#REF!="All")+(iPhone_Sales_Data!$F$2:$F$7001=#REF!)>0),--((#REF!="All")+(iPhone_Sales_Data!$C$2:$C$7001=#REF!)>0),--((#REF!="All")+(iPhone_Sales_Data!$D$2:$D$7001=#REF!)>0),--((#REF!="All")+(iPhone_Sales_Data!$E$2:$E$7001=#REF!)>0),--(iPhone_Sales_Data!$C$2:$C$7001=A2),iPhone_Sales_Data!$H$2:$H$7001) -> #REF! | D2: Australia | E2: =SUMPRODUCT(--((#REF!="All")+(iPhone_Sales_Data!$M$2:$M$7001=#REF!)>0),--((#REF!="All")+(iPhone_Sales_Data!$G$2:$G$7001=#REF!)>0),--((#REF!="All")+(iPhone_Sales_Data!$F$2:$F$7001=#REF!)>0),--((#REF!="All")+(iPhone_Sales_Data!$C$2:$C$7001=#REF!)>0),--((#REF!="All")+(iPhone_Sales_Data!$D$2:$D$7001=#REF!)>0),--((#REF!="All")+(iPhone_Sales_Data!$E$2:$E$7001=#REF!)>0),--(iPhone_Sales_Data!$F$2:$F$7001=D2),iPhone_Sales_Data!$J$2:$J$7001) -> #REF! | G2: 128GB | H2: =SUMPRODUCT(--((#REF!="All")+(iPhone_Sales_Data!$M$2:$M$7001=#REF!)>0),--((#REF!="All")+(iPhone_Sales_Data!$G$2:$G$7001=#REF!)>0),--((#REF!="All")+(iPhone_Sales_Data!$F$2:$F$7001=#REF!)>0),--((#REF!="All")+(iPhone_Sales_Data!$C$2:$C$7001=#REF!)>0),--((#REF!="All")+(iPhone_Sales_Data!$D$2:$D$7001=#REF!)>0),--((#REF!="All")+(iPhone_Sales_Data!$E$2:$E$7001=#REF!)>0),--(iPhone_Sales_Data!$D$2:$D$7001=G2),iPhone_Sales_Data!$J$2:$J$7001) -> #REF! | J2: Black | K2: =SUMPRODUCT(--((#REF!="All")+(iPhone_Sales_Data!$M$2:$M$7001=#REF!)>0),--((#REF!="All")+(iPhone_Sales_Data!$G$2:$G$7001=#REF!)>0),--((#REF!="All")+(iPhone_Sales_Data!$F$2:$F$7001=#REF!)>0),--((#REF!="All")+(iPhone_Sales_Data!$C$2:$C$7001=#REF!)>0),--((#REF!="All")+(iPhone_Sales_Data!$D$2:$D$7001=#REF!)>0),--((#REF!="All")+(iPhone_Sales_Data!$E$2:$E$7001=#REF!)>0),--(iPhone_Sales_Data!$E$2:$E$7001=J2),iPhone_Sales_Data!$H$2:$H$7001) -> #REF! | M2: Female | N2: =SUMPRODUCT(--((#REF!="All")+(iPhone_Sales_Data!$M$2:$M$7001=#REF!)>0),--((#REF!="All")+(iPhone_Sales_Data!$G$2:$G$7001=#REF!)>0),--((#REF!="All")+(iPhone_Sales_Data!$F$2:$F$7001=#REF!)>0),--((#REF!="All")+(iPhone_Sales_Data!$C$2:$C$7001=#REF!)>0),--((#REF!="All")+(iPhone_Sales_Data!$D$2:$D$7001=#REF!)>0),--((#REF!="All")+(iPhone_Sales_Data!$E$2:$E$7001=#REF!)>0),--(iPhone_Sales_Data!$G$2:$G$7001=M2),iPhone_Sales_Data!$J$2:$J$7001) -> #REF! | P2: Jan-2025 | Q2: =SUMPRODUCT(--((#REF!="All")+(iPhone_Sales_Data!$M$2:$M$7001=#REF!)>0),--((#REF!="All")+(iPhone_Sales_Data!$G$2:$G$7001=#REF!)>0),--((#REF!="All")+(iPhone_Sales_Data!$F$2:$F$7001=#REF!)>0),--((#REF!="All")+(iPhone_Sales_Data!$C$2:$C$7001=#REF!)>0),--((#REF!="All")+(iPhone_Sales_Data!$D$2:$D$7001=#REF!)>0),--((#REF!="All")+(iPhone_Sales_Data!$E$2:$E$7001=#REF!)>0),--(iPhone_Sales_Data!$L$2:$L$7001=P2),iPhone_Sales_Data!$J$2:$J$7001) -> #REF!
A3: iPhone 14 | B3: =SUMPRODUCT(--((#REF!="All")+(iPhone_Sales_Data!$M$2:$M$7001=#REF!)>0),--((#REF!="All")+(iPhone_Sales_Data!$G$2:$G$7001=#REF!)>0),--((#REF!="All")+(iPhone_Sales_Data!$F$2:$F$7001=#REF!)>0),--((#REF!="All")+(iPhone_Sales_Data!$C$2:$C$7001=#REF!)>0),--((#REF!="All")+(iPhone_Sales_Data!$D$2:$D$7001=#REF!)>0),--((#REF!="All")+(iPhone_Sales_Data!$E$2:$E$7001=#REF!)>0),--(iPhone_Sales_Data!$C$2:$C$7001=A3),iPhone_Sales_Data!$H$2:$H$7001) -> #REF! | D3: Canada | E3: =SUMPRODUCT(--((#REF!="All")+(iPhone_Sales_Data!$M$2:$M$7001=#REF!)>0),--((#REF!="All")+(iPhone_Sales_Data!$G$2:$G$7001=#REF!)>0),--((#REF!="All")+(iPhone_Sales_Data!$F$2:$F$7001=#REF!)>0),--((#REF!="All")+(iPhone_Sales_Data!$C$2:$C$7001=#REF!)>0),--((#REF!="All")+(iPhone_Sales_Data!$D$2:$D$7001=#REF!)>0),--((#REF!="All")+(iPhone_Sales_Data!$E$2:$E$7001=#REF!)>0),--(iPhone_Sales_Data!$F$2:$F$7001=D3),iPhone_Sales_Data!$J$2:$J$7001) -> #REF! | G3: 1TB | H3: =SUMPRODUCT(--((#REF!="All")+(iPhone_Sales_Data!$M$2:$M$7001=#REF!)>0),--((#REF!="All")+(iPhone_Sales_Data!$G$2:$G$7001=#REF!)>0),--((#REF!="All")+(iPhone_Sales_Data!$F$2:$F$7001=#REF!)>0),--((#REF!="All")+(iPhone_Sales_Data!$C$2:$C$7001=#REF!)>0),--((#REF!="All")+(iPhone_Sales_Data!$D$2:$D$7001=#REF!)>0),--((#REF!="All")+(iPhone_Sales_Data!$E$2:$E$7001=#REF!)>0),--(iPhone_Sales_Data!$D$2:$D$7001=G3),iPhone_Sales_Data!$J$2:$J$7001) -> #REF! | J3: Blue | K3: =SUMPRODUCT(--((#REF!="All")+(iPhone_Sales_Data!$M$2:$M$7001=#REF!)>0),--((#REF!="All")+(iPhone_Sales_Data!$G$2:$G$7001=#REF!)>0),--((#REF!="All")+(iPhone_Sales_Data!$F$2:$F$7001=#REF!)>0),--((#REF!="All")+(iPhone_Sales_Data!$C$2:$C$7001=#REF!)>0),--((#REF!="All")+(iPhone_Sales_Data!$D$2:$D$7001=#REF!)>0),--((#REF!="All")+(iPhone_Sales_Data!$E$2:$E$7001=#REF!)>0),--(iPhone_Sales_Data!$E$2:$E$7001=J3),iPhone_Sales_Data!$H$2:$H$7001) -> #REF! | M3: Male | N3: =SUMPRODUCT(--((#REF!="All")+(iPhone_Sales_Data!$M$2:$M$7001=#REF!)>0),--((#REF!="All")+(iPhone_Sales_Data!$G$2:$G$7001=#REF!)>0),--((#REF!="All")+(iPhone_Sales_Data!$F$2:$F$7001=#REF!)>0),--((#REF!="All")+(iPhone_Sales_Data!$C$2:$C$7001=#REF!)>0),--((#REF!="All")+(iPhone_Sales_Data!$D$2:$D$7001=#REF!)>0),--((#REF!="All")+(iPhone_Sales_Data!$E$2:$E$7001=#REF!)>0),--(iPhone_Sales_Data!$G$2:$G$7001=M3),iPhone_Sales_Data!$J$2:$J$7001) -> #REF! | P3: Feb-2025 | Q3: =SUMPRODUCT(--((#REF!="All")+(iPhone_Sales_Data!$M$2:$M$7001=#REF!)>0),--((#REF!="All")+(iPhone_Sales_Data!$G$2:$G$7001=#REF!)>0),--((#REF!="All")+(iPhone_Sales_Data!$F$2:$F$7001=#REF!)>0),--((#REF!="All")+(iPhone_Sales_Data!$C$2:$C$7001=#REF!)>0),--((#REF!="All")+(iPhone_Sales_Data!$D$2:$D$7001=#REF!)>0),--((#REF!="All")+(iPhone_Sales_Data!$E$2:$E$7001=#REF!)>0),--(iPhone_Sales_Data!$L$2:$L$7001=P3),iPhone_Sales_Data!$J$2:$J$7001) -> #REF!
A4: iPhone 15 | B4: =SUMPRODUCT(--((#REF!="All")+(iPhone_Sales_Data!$M$2:$M$7001=#REF!)>0),--((#REF!="All")+(iPhone_Sales_Data!$G$2:$G$7001=#REF!)>0),--((#REF!="All")+(iPhone_Sales_Data!$F$2:$F$7001=#REF!)>0),--((#REF!="All")+(iPhone_Sales_Data!$C$2:$C$7001=#REF!)>0),--((#REF!="All")+(iPhone_Sales_Data!$D$2:$D$7001=#REF!)>0),--((#REF!="All")+(iPhone_Sales_Data!$E$2:$E$7001=#REF!)>0),--(iPhone_Sales_Data!$C$2:$C$7001=A4),iPhone_Sales_Data!$H$2:$H$7001) -> #REF! | D4: Germany | E4: =SUMPRODUCT(--((#REF!="All")+(iPhone_Sales_Data!$M$2:$M$7001=#REF!)>0),--((#REF!="All")+(iPhone_Sales_Data!$G$2:$G$7001=#REF!)>0),--((#REF!="All")+(iPhone_Sales_Data!$F$2:$F$7001=#REF!)>0),--((#REF!="All")+(iPhone_Sales_Data!$C$2:$C$7001=#REF!)>0),--((#REF!="All")+(iPhone_Sales_Data!$D$2:$D$7001=#REF!)>0),--((#REF!="All")+(iPhone_Sales_Data!$E$2:$E$7001=#REF!)>0),--(iPhone_Sales_Data!$F$2:$F$7001=D4),iPhone_Sales_Data!$J$2:$J$7001) -> #REF! | G4: 256GB | H4: =SUMPRODUCT(--((#REF!="All")+(iPhone_Sales_Data!$M$2:$M$7001=#REF!)>0),--((#REF!="All")+(iPhone_Sales_Data!$G$2:$G$7001=#REF!)>0),--((#REF!="All")+(iPhone_Sales_Data!$F$2:$F$7001=#REF!)>0),--((#REF!="All")+(iPhone_Sales_Data!$C$2:$C$7001=#REF!)>0),--((#REF!="All")+(iPhone_Sales_Data!$D$2:$D$7001=#REF!)>0),--((#REF!="All")+(iPhone_Sales_Data!$E$2:$E$7001=#REF!)>0),--(iPhone_Sales_Data!$D$2:$D$7001=G4),iPhone_Sales_Data!$J$2:$J$7001) -> #REF! | J4: Green | K4: =SUMPRODUCT(--((#REF!="All")+(iPhone_Sales_Data!$M$2:$M$7001=#REF!)>0),--((#REF!="All")+(iPhone_Sales_Data!$G$2:$G$7001=#REF!)>0),--((#REF!="All")+(iPhone_Sales_Data!$F$2:$F$7001=#REF!)>0),--((#REF!="All")+(iPhone_Sales_Data!$C$2:$C$7001=#REF!)>0),--((#REF!="All")+(iPhone_Sales_Data!$D$2:$D$7001=#REF!)>0),--((#REF!="All")+(iPhone_Sales_Data!$E$2:$E$7001=#REF!)>0),--(iPhone_Sales_Data!$E$2:$E$7001=J4),iPhone_Sales_Data!$H$2:$H$7001) -> #REF! | P4: Mar-2025 | Q4: =SUMPRODUCT(--((#REF!="All")+(iPhone_Sales_Data!$M$2:$M$7001=#REF!)>0),--((#REF!="All")+(iPhone_Sales_Data!$G$2:$G$7001=#REF!)>0),--((#REF!="All")+(iPhone_Sales_Data!$F$2:$F$7001=#REF!)>0),--((#REF!="All")+(iPhone_Sales_Data!$C$2:$C$7001=#REF!)>0),--((#REF!="All")+(iPhone_Sales_Data!$D$2:$D$7001=#REF!)>0),--((#REF!="All")+(iPhone_Sales_Data!$E$2:$E$7001=#REF!)>0),--(iPhone_Sales_Data!$L$2:$L$7001=P4),iPhone_Sales_Data!$J$2:$J$7001) -> #REF!
A5: iPhone 15 Pro | B5: =SUMPRODUCT(--((#REF!="All")+(iPhone_Sales_Data!$M$2:$M$7001=#REF!)>0),--((#REF!="All")+(iPhone_Sales_Data!$G$2:$G$7001=#REF!)>0),--((#REF!="All")+(iPhone_Sales_Data!$F$2:$F$7001=#REF!)>0),--((#REF!="All")+(iPhone_Sales_Data!$C$2:$C$7001=#REF!)>0),--((#REF!="All")+(iPhone_Sales_Data!$D$2:$D$7001=#REF!)>0),--((#REF!="All")+(iPhone_Sales_Data!$E$2:$E$7001=#REF!)>0),--(iPhone_Sales_Data!$C$2:$C$7001=A5),iPhone_Sales_Data!$H$2:$H$7001) -> #REF! | D5: India | E5: =SUMPRODUCT(--((#REF!="All")+(iPhone_Sales_Data!$M$2:$M$7001=#REF!)>0),--((#REF!="All")+(iPhone_Sales_Data!$G$2:$G$7001=#REF!)>0),--((#REF!="All")+(iPhone_Sales_Data!$F$2:$F$7001=#REF!)>0),--((#REF!="All")+(iPhone_Sales_Data!$C$2:$C$7001=#REF!)>0),--((#REF!="All")+(iPhone_Sales_Data!$D$2:$D$7001=#REF!)>0),--((#REF!="All")+(iPhone_Sales_Data!$E$2:$E$7001=#REF!)>0),--(iPhone_Sales_Data!$F$2:$F$7001=D5),iPhone_Sales_Data!$J$2:$J$7001) -> #REF! | G5: 512GB | H5: =SUMPRODUCT(--((#REF!="All")+(iPhone_Sales_Data!$M$2:$M$7001=#REF!)>0),--((#REF!="All")+(iPhone_Sales_Data!$G$2:$G$7001=#REF!)>0),--((#REF!="All")+(iPhone_Sales_Data!$F$2:$F$7001=#REF!)>0),--((#REF!="All")+(iPhone_Sales_Data!$C$2:$C$7001=#REF!)>0),--((#REF!="All")+(iPhone_Sales_Data!$D$2:$D$7001=#REF!)>0),--((#REF!="All")+(iPhone_Sales_Data!$E$2:$E$7001=#REF!)>0),--(iPhone_Sales_Data!$D$2:$D$7001=G5),iPhone_Sales_Data!$J$2:$J$7001) -> #REF! | J5: Natural Titanium | K5: =SUMPRODUCT(--((#REF!="All")+(iPhone_Sales_Data!$M$2:$M$7001=#REF!)>0),--((#REF!="All")+(iPhone_Sales_Data!$G$2:$G$7001=#REF!)>0),--((#REF!="All")+(iPhone_Sales_Data!$F$2:$F$7001=#REF!)>0),--((#REF!="All")+(iPhone_Sales_Data!$C$2:$C$7001=#REF!)>0),--((#REF!="All")+(iPhone_Sales_Data!$D$2:$D$7001=#REF!)>0),--((#REF!="All")+(iPhone_Sales_Data!$E$2:$E$7001=#REF!)>0),--(iPhone_Sales_Data!$E$2:$E$7001=J5),iPhone_Sales_Data!$H$2:$H$7001) -> #REF! | P5: Apr-2025 | Q5: =SUMPRODUCT(--((#REF!="All")+(iPhone_Sales_Data!$M$2:$M$7001=#REF!)>0),--((#REF!="All")+(iPhone_Sales_Data!$G$2:$G$7001=#REF!)>0),--((#REF!="All")+(iPhone_Sales_Data!$F$2:$F$7001=#REF!)>0),--((#REF!="All")+(iPhone_Sales_Data!$C$2:$C$7001=#REF!)>0),--((#REF!="All")+(iPhone_Sales_Data!$D$2:$D$7001=#REF!)>0),--((#REF!="All")+(iPhone_Sales_Data!$E$2:$E$7001=#REF!)>0),--(iPhone_Sales_Data!$L$2:$L$7001=P5),iPhone_Sales_Data!$J$2:$J$7001) -> #REF!
A6: iPhone 15 Pro Max | B6: =SUMPRODUCT(--((#REF!="All")+(iPhone_Sales_Data!$M$2:$M$7001=#REF!)>0),--((#REF!="All")+(iPhone_Sales_Data!$G$2:$G$7001=#REF!)>0),--((#REF!="All")+(iPhone_Sales_Data!$F$2:$F$7001=#REF!)>0),--((#REF!="All")+(iPhone_Sales_Data!$C$2:$C$7001=#REF!)>0),--((#REF!="All")+(iPhone_Sales_Data!$D$2:$D$7001=#REF!)>0),--((#REF!="All")+(iPhone_Sales_Data!$E$2:$E$7001=#REF!)>0),--(iPhone_Sales_Data!$C$2:$C$7001=A6),iPhone_Sales_Data!$H$2:$H$7001) -> #REF! | D6: Singapore | E6: =SUMPRODUCT(--((#REF!="All")+(iPhone_Sales_Data!$M$2:$M$7001=#REF!)>0),--((#REF!="All")+(iPhone_Sales_Data!$G$2:$G$7001=#REF!)>0),--((#REF!="All")+(iPhone_Sales_Data!$F$2:$F$7001=#REF!)>0),--((#REF!="All")+(iPhone_Sales_Data!$C$2:$C$7001=#REF!)>0),--((#REF!="All")+(iPhone_Sales_Data!$D$2:$D$7001=#REF!)>0),--((#REF!="All")+(iPhone_Sales_Data!$E$2:$E$7001=#REF!)>0),--(iPhone_Sales_Data!$F$2:$F$7001=D6),iPhone_Sales_Data!$J$2:$J$7001) -> #REF! | J6: Pink | K6: =SUMPRODUCT(--((#REF!="All")+(iPhone_Sales_Data!$M$2:$M$7001=#REF!)>0),--((#REF!="All")+(iPhone_Sales_Data!$G$2:$G$7001=#REF!)>0),--((#REF!="All")+(iPhone_Sales_Data!$F$2:$F$7001=#REF!)>0),--((#REF!="All")+(iPhone_Sales_Data!$C$2:$C$7001=#REF!)>0),--((#REF!="All")+(iPhone_Sales_Data!$D$2:$D$7001=#REF!)>0),--((#REF!="All")+(iPhone_Sales_Data!$E$2:$E$7001=#REF!)>0),--(iPhone_Sales_Data!$E$2:$E$7001=J6),iPhone_Sales_Data!$H$2:$H$7001) -> #REF! | P6: May-2025 | Q6: =SUMPRODUCT(--((#REF!="All")+(iPhone_Sales_Data!$M$2:$M$7001=#REF!)>0),--((#REF!="All")+(iPhone_Sales_Data!$G$2:$G$7001=#REF!)>0),--((#REF!="All")+(iPhone_Sales_Data!$F$2:$F$7001=#REF!)>0),--((#REF!="All")+(iPhone_Sales_Data!$C$2:$C$7001=#REF!)>0),--((#REF!="All")+(iPhone_Sales_Data!$D$2:$D$7001=#REF!)>0),--((#REF!="All")+(iPhone_Sales_Data!$E$2:$E$7001=#REF!)>0),--(iPhone_Sales_Data!$L$2:$L$7001=P6),iPhone_Sales_Data!$J$2:$J$7001) -> #REF!
A7: iPhone 16 | B7: =SUMPRODUCT(--((#REF!="All")+(iPhone_Sales_Data!$M$2:$M$7001=#REF!)>0),--((#REF!="All")+(iPhone_Sales_Data!$G$2:$G$7001=#REF!)>0),--((#REF!="All")+(iPhone_Sales_Data!$F$2:$F$7001=#REF!)>0),--((#REF!="All")+(iPhone_Sales_Data!$C$2:$C$7001=#REF!)>0),--((#REF!="All")+(iPhone_Sales_Data!$D$2:$D$7001=#REF!)>0),--((#REF!="All")+(iPhone_Sales_Data!$E$2:$E$7001=#REF!)>0),--(iPhone_Sales_Data!$C$2:$C$7001=A7),iPhone_Sales_Data!$H$2:$H$7001) -> #REF! | D7: UAE | E7: =SUMPRODUCT(--((#REF!="All")+(iPhone_Sales_Data!$M$2:$M$7001=#REF!)>0),--((#REF!="All")+(iPhone_Sales_Data!$G$2:$G$7001=#REF!)>0),--((#REF!="All")+(iPhone_Sales_Data!$F$2:$F$7001=#REF!)>0),--((#REF!="All")+(iPhone_Sales_Data!$C$2:$C$7001=#REF!)>0),--((#REF!="All")+(iPhone_Sales_Data!$D$2:$D$7001=#REF!)>0),--((#REF!="All")+(iPhone_Sales_Data!$E$2:$E$7001=#REF!)>0),--(iPhone_Sales_Data!$F$2:$F$7001=D7),iPhone_Sales_Data!$J$2:$J$7001) -> #REF! | J7: Purple | K7: =SUMPRODUCT(--((#REF!="All")+(iPhone_Sales_Data!$M$2:$M$7001=#REF!)>0),--((#REF!="All")+(iPhone_Sales_Data!$G$2:$G$7001=#REF!)>0),--((#REF!="All")+(iPhone_Sales_Data!$F$2:$F$7001=#REF!)>0),--((#REF!="All")+(iPhone_Sales_Data!$C$2:$C$7001=#REF!)>0),--((#REF!="All")+(iPhone_Sales_Data!$D$2:$D$7001=#REF!)>0),--((#REF!="All")+(iPhone_Sales_Data!$E$2:$E$7001=#REF!)>0),--(iPhone_Sales_Data!$E$2:$E$7001=J7),iPhone_Sales_Data!$H$2:$H$7001) -> #REF! | P7: Jun-2025 | Q7: =SUMPRODUCT(--((#REF!="All")+(iPhone_Sales_Data!$M$2:$M$7001=#REF!)>0),--((#REF!="All")+(iPhone_Sales_Data!$G$2:$G$7001=#REF!)>0),--((#REF!="All")+(iPhone_Sales_Data!$F$2:$F$7001=#REF!)>0),--((#REF!="All")+(iPhone_Sales_Data!$C$2:$C$7001=#REF!)>0),--((#REF!="All")+(iPhone_Sales_Data!$D$2:$D$7001=#REF!)>0),--((#REF!="All")+(iPhone_Sales_Data!$E$2:$E$7001=#REF!)>0),--(iPhone_Sales_Data!$L$2:$L$7001=P7),iPhone_Sales_Data!$J$2:$J$7001) -> #REF!
A8: iPhone 16 Plus | B8: =SUMPRODUCT(--((#REF!="All")+(iPhone_Sales_Data!$M$2:$M$7001=#REF!)>0),--((#REF!="All")+(iPhone_Sales_Data!$G$2:$G$7001=#REF!)>0),--((#REF!="All")+(iPhone_Sales_Data!$F$2:$F$7001=#REF!)>0),--((#REF!="All")+(iPhone_Sales_Data!$C$2:$C$7001=#REF!)>0),--((#REF!="All")+(iPhone_Sales_Data!$D$2:$D$7001=#REF!)>0),--((#REF!="All")+(iPhone_Sales_Data!$E$2:$E$7001=#REF!)>0),--(iPhone_Sales_Data!$C$2:$C$7001=A8),iPhone_Sales_Data!$H$2:$H$7001) -> #REF! | D8: UK | E8: =SUMPRODUCT(--((#REF!="All")+(iPhone_Sales_Data!$M$2:$M$7001=#REF!)>0),--((#REF!="All")+(iPhone_Sales_Data!$G$2:$G$7001=#REF!)>0),--((#REF!="All")+(iPhone_Sales_Data!$F$2:$F$7001=#REF!)>0),--((#REF!="All")+(iPhone_Sales_Data!$C$2:$C$7001=#REF!)>0),--((#REF!="All")+(iPhone_Sales_Data!$D$2:$D$7001=#REF!)>0),--((#REF!="All")+(iPhone_Sales_Data!$E$2:$E$7001=#REF!)>0),--(iPhone_Sales_Data!$F$2:$F$7001=D8),iPhone_Sales_Data!$J$2:$J$7001) -> #REF! | J8: White | K8: =SUMPRODUCT(--((#REF!="All")+(iPhone_Sales_Data!$M$2:$M$7001=#REF!)>0),--((#REF!="All")+(iPhone_Sales_Data!$G$2:$G$7001=#REF!)>0),--((#REF!="All")+(iPhone_Sales_Data!$F$2:$F$7001=#REF!)>0),--((#REF!="All")+(iPhone_Sales_Data!$C$2:$C$7001=#REF!)>0),--((#REF!="All")+(iPhone_Sales_Data!$D$2:$D$7001=#REF!)>0),--((#REF!="All")+(iPhone_Sales_Data!$E$2:$E$7001=#REF!)>0),--(iPhone_Sales_Data!$E$2:$E$7001=J8),iPhone_Sales_Data!$H$2:$H$7001) -> #REF! | P8: Jul-2025 | Q8: =SUMPRODUCT(--((#REF!="All")+(iPhone_Sales_Data!$M$2:$M$7001=#REF!)>0),--((#REF!="All")+(iPhone_Sales_Data!$G$2:$G$7001=#REF!)>0),--((#REF!="All")+(iPhone_Sales_Data!$F$2:$F$7001=#REF!)>0),--((#REF!="All")+(iPhone_Sales_Data!$C$2:$C$7001=#REF!)>0),--((#REF!="All")+(iPhone_Sales_Data!$D$2:$D$7001=#REF!)>0),--((#REF!="All")+(iPhone_Sales_Data!$E$2:$E$7001=#REF!)>0),--(iPhone_Sales_Data!$L$2:$L$7001=P8),iPhone_Sales_Data!$J$2:$J$7001) -> #REF!
A9: iPhone 16 Pro | B9: =SUMPRODUCT(--((#REF!="All")+(iPhone_Sales_Data!$M$2:$M$7001=#REF!)>0),--((#REF!="All")+(iPhone_Sales_Data!$G$2:$G$7001=#REF!)>0),--((#REF!="All")+(iPhone_Sales_Data!$F$2:$F$7001=#REF!)>0),--((#REF!="All")+(iPhone_Sales_Data!$C$2:$C$7001=#REF!)>0),--((#REF!="All")+(iPhone_Sales_Data!$D$2:$D$7001=#REF!)>0),--((#REF!="All")+(iPhone_Sales_Data!$E$2:$E$7001=#REF!)>0),--(iPhone_Sales_Data!$C$2:$C$7001=A9),iPhone_Sales_Data!$H$2:$H$7001) -> #REF! | D9: USA | E9: =SUMPRODUCT(--((#REF!="All")+(iPhone_Sales_Data!$M$2:$M$7001=#REF!)>0),--((#REF!="All")+(iPhone_Sales_Data!$G$2:$G$7001=#REF!)>0),--((#REF!="All")+(iPhone_Sales_Data!$F$2:$F$7001=#REF!)>0),--((#REF!="All")+(iPhone_Sales_Data!$C$2:$C$7001=#REF!)>0),--((#REF!="All")+(iPhone_Sales_Data!$D$2:$D$7001=#REF!)>0),--((#REF!="All")+(iPhone_Sales_Data!$E$2:$E$7001=#REF!)>0),--(iPhone_Sales_Data!$F$2:$F$7001=D9),iPhone_Sales_Data!$J$2:$J$7001) -> #REF! | P9: Aug-2025 | Q9: =SUMPRODUCT(--((#REF!="All")+(iPhone_Sales_Data!$M$2:$M$7001=#REF!)>0),--((#REF!="All")+(iPhone_Sales_Data!$G$2:$G$7001=#REF!)>0),--((#REF!="All")+(iPhone_Sales_Data!$F$2:$F$7001=#REF!)>0),--((#REF!="All")+(iPhone_Sales_Data!$C$2:$C$7001=#REF!)>0),--((#REF!="All")+(iPhone_Sales_Data!$D$2:$D$7001=#REF!)>0),--((#REF!="All")+(iPhone_Sales_Data!$E$2:$E$7001=#REF!)>0),--(iPhone_Sales_Data!$L$2:$L$7001=P9),iPhone_Sales_Data!$J$2:$J$7001) -> #REF!
A10: iPhone 16 Pro Max | B10: =SUMPRODUCT(--((#REF!="All")+(iPhone_Sales_Data!$M$2:$M$7001=#REF!)>0),--((#REF!="All")+(iPhone_Sales_Data!$G$2:$G$7001=#REF!)>0),--((#REF!="All")+(iPhone_Sales_Data!$F$2:$F$7001=#REF!)>0),--((#REF!="All")+(iPhone_Sales_Data!$C$2:$C$7001=#REF!)>0),--((#REF!="All")+(iPhone_Sales_Data!$D$2:$D$7001=#REF!)>0),--((#REF!="All")+(iPhone_Sales_Data!$E$2:$E$7001=#REF!)>0),--(iPhone_Sales_Data!$C$2:$C$7001=A10),iPhone_Sales_Data!$H$2:$H$7001) -> #REF! | P10: Sep-2025 | Q10: =SUMPRODUCT(--((#REF!="All")+(iPhone_Sales_Data!$M$2:$M$7001=#REF!)>0),--((#REF!="All")+(iPhone_Sales_Data!$G$2:$G$7001=#REF!)>0),--((#REF!="All")+(iPhone_Sales_Data!$F$2:$F$7001=#REF!)>0),--((#REF!="All")+(iPhone_Sales_Data!$C$2:$C$7001=#REF!)>0),--((#REF!="All")+(iPhone_Sales_Data!$D$2:$D$7001=#REF!)>0),--((#REF!="All")+(iPhone_Sales_Data!$E$2:$E$7001=#REF!)>0),--(iPhone_Sales_Data!$L$2:$L$7001=P10),iPhone_Sales_Data!$J$2:$J$7001) -> #REF!
P11: Oct-2025 | Q11: =SUMPRODUCT(--((#REF!="All")+(iPhone_Sales_Data!$M$2:$M$7001=#REF!)>0),--((#REF!="All")+(iPhone_Sales_Data!$G$2:$G$7001=#REF!)>0),--((#REF!="All")+(iPhone_Sales_Data!$F$2:$F$7001=#REF!)>0),--((#REF!="All")+(iPhone_Sales_Data!$C$2:$C$7001=#REF!)>0),--((#REF!="All")+(iPhone_Sales_Data!$D$2:$D$7001=#REF!)>0),--((#REF!="All")+(iPhone_Sales_Data!$E$2:$E$7001=#REF!)>0),--(iPhone_Sales_Data!$L$2:$L$7001=P11),iPhone_Sales_Data!$J$2:$J$7001) -> #REF!
P12: Nov-2025 | Q12: =SUMPRODUCT(--((#REF!="All")+(iPhone_Sales_Data!$M$2:$M$7001=#REF!)>0),--((#REF!="All")+(iPhone_Sales_Data!$G$2:$G$7001=#REF!)>0),--((#REF!="All")+(iPhone_Sales_Data!$F$2:$F$7001=#REF!)>0),--((#REF!="All")+(iPhone_Sales_Data!$C$2:$C$7001=#REF!)>0),--((#REF!="All")+(iPhone_Sales_Data!$D$2:$D$7001=#REF!)>0),--((#REF!="All")+(iPhone_Sales_Data!$E$2:$E$7001=#REF!)>0),--(iPhone_Sales_Data!$L$2:$L$7001=P12),iPhone_Sales_Data!$J$2:$J$7001) -> #REF!
P13: Dec-2025 | Q13: =SUMPRODUCT(--((#REF!="All")+(iPhone_Sales_Data!$M$2:$M$7001=#REF!)>0),--((#REF!="All")+(iPhone_Sales_Data!$G$2:$G$7001=#REF!)>0),--((#REF!="All")+(iPhone_Sales_Data!$F$2:$F$7001=#REF!)>0),--((#REF!="All")+(iPhone_Sales_Data!$C$2:$C$7001=#REF!)>0),--((#REF!="All")+(iPhone_Sales_Data!$D$2:$D$7001=#REF!)>0),--((#REF!="All")+(iPhone_Sales_Data!$E$2:$E$7001=#REF!)>0),--(iPhone_Sales_Data!$L$2:$L$7001=P13),iPhone_Sales_Data!$J$2:$J$7001) -> #REF!
P14: Jan-2026 | Q14: =SUMPRODUCT(--((#REF!="All")+(iPhone_Sales_Data!$M$2:$M$7001=#REF!)>0),--((#REF!="All")+(iPhone_Sales_Data!$G$2:$G$7001=#REF!)>0),--((#REF!="All")+(iPhone_Sales_Data!$F$2:$F$7001=#REF!)>0),--((#REF!="All")+(iPhone_Sales_Data!$C$2:$C$7001=#REF!)>0),--((#REF!="All")+(iPhone_Sales_Data!$D$2:$D$7001=#REF!)>0),--((#REF!="All")+(iPhone_Sales_Data!$E$2:$E$7001=#REF!)>0),--(iPhone_Sales_Data!$L$2:$L$7001=P14),iPhone_Sales_Data!$J$2:$J$7001) -> #REF!
P15: Feb-2026 | Q15: =SUMPRODUCT(--((#REF!="All")+(iPhone_Sales_Data!$M$2:$M$7001=#REF!)>0),--((#REF!="All")+(iPhone_Sales_Data!$G$2:$G$7001=#REF!)>0),--((#REF!="All")+(iPhone_Sales_Data!$F$2:$F$7001=#REF!)>0),--((#REF!="All")+(iPhone_Sales_Data!$C$2:$C$7001=#REF!)>0),--((#REF!="All")+(iPhone_Sales_Data!$D$2:$D$7001=#REF!)>0),--((#REF!="All")+(iPhone_Sales_Data!$E$2:$E$7001=#REF!)>0),--(iPhone_Sales_Data!$L$2:$L$7001=P15),iPhone_Sales_Data!$J$2:$J$7001) -> #REF!
P16: Mar-2026 | Q16: =SUMPRODUCT(--((#REF!="All")+(iPhone_Sales_Data!$M$2:$M$7001=#REF!)>0),--((#REF!="All")+(iPhone_Sales_Data!$G$2:$G$7001=#REF!)>0),--((#REF!="All")+(iPhone_Sales_Data!$F$2:$F$7001=#REF!)>0),--((#REF!="All")+(iPhone_Sales_Data!$C$2:$C$7001=#REF!)>0),--((#REF!="All")+(iPhone_Sales_Data!$D$2:$D$7001=#REF!)>0),--((#REF!="All")+(iPhone_Sales_Data!$E$2:$E$7001=#REF!)>0),--(iPhone_Sales_Data!$L$2:$L$7001=P16),iPhone_Sales_Data!$J$2:$J$7001) -> #REF!
P17: Apr-2026 | Q17: =SUMPRODUCT(--((#REF!="All")+(iPhone_Sales_Data!$M$2:$M$7001=#REF!)>0),--((#REF!="All")+(iPhone_Sales_Data!$G$2:$G$7001=#REF!)>0),--((#REF!="All")+(iPhone_Sales_Data!$F$2:$F$7001=#REF!)>0),--((#REF!="All")+(iPhone_Sales_Data!$C$2:$C$7001=#REF!)>0),--((#REF!="All")+(iPhone_Sales_Data!$D$2:$D$7001=#REF!)>0),--((#REF!="All")+(iPhone_Sales_Data!$E$2:$E$7001=#REF!)>0),--(iPhone_Sales_Data!$L$2:$L$7001=P17),iPhone_Sales_Data!$J$2:$J$7001) -> #REF!
P18: May-2026 | Q18: =SUMPRODUCT(--((#REF!="All")+(iPhone_Sales_Data!$M$2:$M$7001=#REF!)>0),--((#REF!="All")+(iPhone_Sales_Data!$G$2:$G$7001=#REF!)>0),--((#REF!="All")+(iPhone_Sales_Data!$F$2:$F$7001=#REF!)>0),--((#REF!="All")+(iPhone_Sales_Data!$C$2:$C$7001=#REF!)>0),--((#REF!="All")+(iPhone_Sales_Data!$D$2:$D$7001=#REF!)>0),--((#REF!="All")+(iPhone_Sales_Data!$E$2:$E$7001=#REF!)>0),--(iPhone_Sales_Data!$L$2:$L$7001=P18),iPhone_Sales_Data!$J$2:$J$7001) -> #REF!
P19: Jun-2026 | Q19: =SUMPRODUCT(--((#REF!="All")+(iPhone_Sales_Data!$M$2:$M$7001=#REF!)>0),--((#REF!="All")+(iPhone_Sales_Data!$G$2:$G$7001=#REF!)>0),--((#REF!="All")+(iPhone_Sales_Data!$F$2:$F$7001=#REF!)>0),--((#REF!="All")+(iPhone_Sales_Data!$C$2:$C$7001=#REF!)>0),--((#REF!="All")+(iPhone_Sales_Data!$D$2:$D$7001=#REF!)>0),--((#REF!="All")+(iPhone_Sales_Data!$E$2:$E$7001=#REF!)>0),--(iPhone_Sales_Data!$L$2:$L$7001=P19),iPhone_Sales_Data!$J$2:$J$7001) -> #REF!
P20: Jul-2026 | Q20: =SUMPRODUCT(--((#REF!="All")+(iPhone_Sales_Data!$M$2:$M$7001=#REF!)>0),--((#REF!="All")+(iPhone_Sales_Data!$G$2:$G$7001=#REF!)>0),--((#REF!="All")+(iPhone_Sales_Data!$F$2:$F$7001=#REF!)>0),--((#REF!="All")+(iPhone_Sales_Data!$C$2:$C$7001=#REF!)>0),--((#REF!="All")+(iPhone_Sales_Data!$D$2:$D$7001=#REF!)>0),--((#REF!="All")+(iPhone_Sales_Data!$E$2:$E$7001=#REF!)>0),--(iPhone_Sales_Data!$L$2:$L$7001=P20),iPhone_Sales_Data!$J$2:$J$7001) -> #REF!
P21: Aug-2026 | Q21: =SUMPRODUCT(--((#REF!="All")+(iPhone_Sales_Data!$M$2:$M$7001=#REF!)>0),--((#REF!="All")+(iPhone_Sales_Data!$G$2:$G$7001=#REF!)>0),--((#REF!="All")+(iPhone_Sales_Data!$F$2:$F$7001=#REF!)>0),--((#REF!="All")+(iPhone_Sales_Data!$C$2:$C$7001=#REF!)>0),--((#REF!="All")+(iPhone_Sales_Data!$D$2:$D$7001=#REF!)>0),--((#REF!="All")+(iPhone_Sales_Data!$E$2:$E$7001=#REF!)>0),--(iPhone_Sales_Data!$L$2:$L$7001=P21),iPhone_Sales_Data!$J$2:$J$7001) -> #REF!
